Workbook
Name all: #REF!

Sheet Sun
A1: CLASS ROUTINE (SCHOOL) - 2026
A2: SUNDAY
A3: SUB | B3: SL | C3: NAME | D3: IST | E3: 2ND | F3: 3RD | G3: 4TH | I3: 5TH | J3: 6TH | K3: 7TH | L3: Total
A4: SUB | B4: SL | C4: NAME | D4: 08.20-09.05 | E4: 09.05-09.45 | F4: 09.45-10.25 | G4: 10.25-11.05 | I4: 11.40-12.25 | J4: 12.25-13.05 | K4: 13.05-13:45
A5: BANGLA | B5: 1 | C5: NA | E5: 10A | G5: 8C | J5: 7D | L5: =COUNTIFS(D5:K5,">""") -> 3
B6: 2 | C6: GA | D6: 9B | E6: 10B | G6: 8A | I6: 6E | L6: =COUNTIFS(D6:K6,">""") -> 4
B7: 3 | C7: MR | E7: 8D | F7: 9BS | I7: 10D | J7: 9A | L7: =COUNTIFS(D7:K7,">""") -> 4
B8: 4 | C8: AS | E8: 6F | F8: 7C | I8: 6G | L8: =COUNTIFS(D8:K8,">""") -> 3
B9: 5 | C9: SN | E9: 6A | G9: 6C | K9: 8B | L9: =COUNTIFS(D9:K9,">""") -> 3
B10: 6 | C10: JU | F10: 9F | I10: 5A | L10: =COUNTIFS(D10:K10,">""") -> 2
B11: 7 | C11: SB | D11: 6C | F11: 4E | G11: 8F | J11: 10E | K11: 7B | L11: =COUNTIFS(D11:K11,">""") -> 5
B12: 8 | C12: KT | D12: 3B | F12: 7F | G12: 10H | J12: 9E | K12: 6B | L12: =COUNTIFS(D12:K12,">""") -> 5
B13: 9 | C13: TC | D13: 9C | F13: 6D | G13: 10BS | I13: 2C-Bhw | K13: 1A | L13: =COUNTIFS(D13:K13,">""") -> 5
B14: 10 | C14: MJH | D14: 9H | F14: 8E | G14: 10F | J14: 6F | K14: 2E | L14: =COUNTIFS(D14:K14,">""") -> 5
B15: 11 | C15: TJA | E15: 9D | I15: 1B | J15: 5C | L15: =COUNTIFS(D15:K15,">""") -> 3
B16: 12 | C16: ARB | D16: 10C | F16: 4A | I16: 8G | J16: 2G | L16: =COUNTIFS(D16:K16,">""") -> 4
B17: 13 | C17: UHP | D17: 8F | F17: 6E | G17: 5D | L17: =COUNTIFS(D17:K17,">""") -> 3
B18: 14 | C18: JHB | E18: 5B | G18: 5G | I18: 2F | K18: 7C | L18: =COUNTIFS(D18:K18,">""") -> 4
B19: 15 | C19: TS | E19: 3G | F19: 5E | I19: 2B | K19: 1D | L19: =COUNTIFS(D19:K19,">""") -> 4
B20: 16 | C20: MAI | D20: 7E | F20: 5F | I20: 1C | J20: 2C | L20: =COUNTIFS(D20:K20,">""") -> 4
A21: ENGLISH | B21: 1 | C21: BCB | D21: 10A | F21: 5B | I21: 7E | J21: 8C | L21: =COUNTIFS(D21:K21,">""") -> 4
B22: 2 | C22: KU | D22: 5E | F22: 6C | G22: 10C | J22: 8A | L22: =COUNTIFS(D22:K22,">""") -> 4
B23: 3 | C23: SHS | D23: 4D | E23: 6B | G23: 7F | I23: 9BS | K23: 9C | L23: =COUNTIFS(D23:K23,">""") -> 5
B24: 4 | C24: NH | D24: 6D | E24: 9A | G24: 5C | I24: 10B | L24: =COUNTIFS(D24:K24,">""") -> 4
B25: 5 | C25: SIS | D25: 7B | F25: 4G | J25: 6D | K25: 8F | L25: =COUNTIFS(D25:K25,">""") -> 4
B26: 6 | C26: MSI | D26: 4A | E26: 10F | I26: 6B | J26: 10H | L26: =COUNTIFS(D26:K26,">""") -> 4
B27: 7 | C27: MSH | D27: 5F | E27: 9F | G27: 7D | I27: 10E | K27: 6A | L27: =COUNTIFS(D27:K27,">""") -> 5
B28: 8 | C28: SJA | E28: 4C | G28: 9H | J28: 8F | K28: 6G | L28: =COUNTIFS(D28:K28,">""") -> 4
B29: 9 | C29: RS | D29: 7C | F29: 6G | G29: 8E | J29: 2B | L29: =COUNTIFS(D29:K29,">""") -> 4
B30: 10 | C30: ZK | D30: 8G | F30: 3C | G30: 6E | J30: 2A | K30: 7D | L30: =COUNTIFS(D30:K30,">""") -> 5
B31: 11 | C31: MAN | D31: 5D | E31: 3B | G31: 9E | J31: 10BS | L31: =COUNTIFS(D31:K31,">""") -> 4
B32: 12 | C32: MHM | D32: 8D | E32: 5G | G32: 3F | J32: 2D | L32: =COUNTIFS(D32:K32,">""") -> 4
B33: 13 | C33: RU | D33: 10D | E33: 5A | I33: 7G | K33: 1F | L33: =COUNTIFS(D33:K33,">""") -> 4
B34: 14 | C34: ISE | D34: 4E | F34: 8B | I34: 1D | K34: 6F | L34: =COUNTIFS(D34:K34,">""") -> 4
B35: 15 | C35: KMA | E35: 7G | G35: 3G | I35: 6C | K35: 2A-Ehw | L35: =COUNTIFS(D35:K35,">""") -> 4
B36: 16 | C36: KKR | E36: 3D | F36: 6F | J36: 2F | K36: 7A | L36: =COUNTIFS(D36:K36,">""") -> 4
A37: MATH | B37: 1 | C37: MFA | G37: 10A | L37: =COUNTIFS(D37:K37,">""") -> 1
B38: 2 | C38: MOH | D38: 10F | F38: 9H | I38: 9B | J38: 10A | L38: =COUNTIFS(D38:K38,">""") -> 4
B39: 3 | C39: NU | D39: 7A | F39: 9E | G39: 10B | J39: 10F | L39: =COUNTIFS(D39:K39,">""") -> 4
B40: 4 | C40: SR | D40: 9BS | F40: 8C | I40: 10C | K40: 9D | L40: =COUNTIFS(D40:K40,">""") -> 4
...

Sheet Mon
A1: CLASS ROUTINE (SCHOOL) - 2026
A2: MONDAY
A3: SUB | B3: SL | C3: NAME | D3: IST | E3: 2ND | F3: 3RD | G3: 4TH | I3: 5TH | J3: 6TH | K3: 7TH | L3: Total
A4: SUB | B4: SL | C4: NAME | D4: 08.20-09.05 | E4: 09.05-09.45 | F4: 09.45-10.25 | G4: 10.25-11.05 | I4: 11.40-12.25 | J4: 12.25-13.05 | K4: 13.05-13:45
A5: BANGLA | B5: 1 | C5: NA | F5: 10B | G5: 9B | J5: 9F | L5: =COUNTIFS(D5:K5,">""") -> 3
B6: 2 | C6: GA | D6: 7D | F6: 10E | I6: 7F | J6: 9B | L6: =COUNTIFS(D6:K6,">""") -> 4
B7: 3 | C7: MR | D7: 6G | E7: 6B | I7: 7B | J7: 9BS | L7: =COUNTIFS(D7:K7,">""") -> 4
B8: 4 | C8: AS | E8: 10D | G8: 9A | I8: 8D | K8: 8E | L8: =COUNTIFS(D8:K8,">""") -> 4
B9: 5 | C9: SN | D9: 8C | E9: 10F | G9: 7A | J9: 6C | L9: =COUNTIFS(D9:K9,">""") -> 4
B10: 6 | C10: JU | F10: 5F | G10: 10A | J10: 8B | L10: =COUNTIFS(D10:K10,">""") -> 3
B11: 7 | C11: SB | E11: 7B | F11: 6C | I11: 2D | J11: 9C | L11: =COUNTIFS(D11:K11,">""") -> 4
B12: 8 | C12: KT | E12: 4C | G12: 3B | I12: 8G | K12: 6B | L12: =COUNTIFS(D12:K12,">""") -> 4
B13: 9 | C13: TC | E13: 4G | F13: 7E | I13: 8A | K13: 6D | L13: =COUNTIFS(D13:K13,">""") -> 4
B14: 10 | C14: MJH | E14: 8E | F14: 6F | J14: 5B | L14: =COUNTIFS(D14:K14,">""") -> 3
B15: 11 | C15: TJA | D15: 10BS | E15: 5E | G15: 3E | I15: 2A | K15: 7G | L15: =COUNTIFS(D15:K15,">""") -> 5
B16: 12 | C16: ARB | E16: 3F | F16: 9E | I16: 7A | J16: 6D | L16: =COUNTIFS(D16:K16,">""") -> 4
B17: 13 | C17: UHP | E17: 3A | F17: 4F | I17: 5D | J17: 10C | L17: =COUNTIFS(D17:K17,">""") -> 4
B18: 14 | C18: JHB | E18: 3C | F18: 4A | I18: 5G | K18: 10H | L18: =COUNTIFS(D18:K18,">""") -> 4
B19: 15 | C19: TS | D19: 4D | F19: 7G | G19: 5C | I19: 1D | L19: =COUNTIFS(D19:K19,">""") -> 4
B20: 16 | C20: MAI | D20: 3D | F20: 5A | I20: 1C | J20: 2E | L20: =COUNTIFS(D20:K20,">""") -> 4
A21: ENGLISH | B21: 1 | C21: BCB | D21: 5B | E21: 9E | I21: 6A | L21: =COUNTIFS(D21:K21,">""") -> 3
B22: 2 | C22: KU | E22: 9H | G22: 6C | I22: 10BS | K22: 9B | L22: =COUNTIFS(D22:K22,">""") -> 4
B23: 3 | C23: SHS | D23: 8A | E23: 10E | I23: 5E | L23: =COUNTIFS(D23:K23,">""") -> 3
B24: 4 | C24: NH | D24: 8B | F24: 7C | G24: 6D | J24: 5C | L24: =COUNTIFS(D24:K24,">""") -> 4
B25: 5 | C25: SIS | D25: 8F | F25: 10C | I25: 2B-Ehw | J25: 5A | L25: =COUNTIFS(D25:K25,">""") -> 4
B26: 6 | C26: MSI | E26: 3E | F26: 6B | J26: 1B-Ehw | K26: 8D | L26: =COUNTIFS(D26:K26,">""") -> 4
B27: 7 | C27: MSH | D27: 6A | E27: 7D | J27: 5F | K27: 2E | L27: =COUNTIFS(D27:K27,">""") -> 4
B28: 8 | C28: SJA | E28: 8F | G28: 4C | I28: 2C | K28: 6G | L28: =COUNTIFS(D28:K28,">""") -> 4
B29: 9 | C29: RS | D29: 10F | F29: 3A | G29: 5D | I29: 7C | K29: 9D | L29: =COUNTIFS(D29:K29,">""") -> 5
B30: 10 | C30: ZK | D30: 9F | E30: 10A | G30: 3C | J30: 2G | L30: =COUNTIFS(D30:K30,">""") -> 4
B31: 11 | C31: MAN | D31: 7B | F31: 6E | I31: 1A | K31: 2F-Ehw | L31: =COUNTIFS(D31:K31,">""") -> 4
B32: 12 | C32: MHM | D32: 5G | F32: 10H | G32: 8D | J32: 7F | L32: =COUNTIFS(D32:K32,">""") -> 4
B33: 13 | C33: RU | E33: 4F | F33: 10D | I33: 9C | J33: 2D-Ehw | L33: =COUNTIFS(D33:K33,">""") -> 4
B34: 14 | C34: ISE | D34: 9A | F34: 4E | G34: 7E | I34: 10D | K34: 2C-Ehw | L34: =COUNTIFS(D34:K34,">""") -> 5
B35: 15 | C35: KMA | D35: 4B | F35: 8E | I35: 2G | K35: 1C | L35: =COUNTIFS(D35:K35,">""") -> 4
B36: 16 | C36: KKR | D36: 8G | F36: 7A | I36: 1G | K36: 6F | L36: =COUNTIFS(D36:K36,">""") -> 4
A37: MATH | B37: 1 | C37: MFA | G37: 1OE | L37: =COUNTIFS(D37:K37,">""") -> 1
B38: 2 | C38: MOH | D38: 9H | F38: 10F | I38: 8C | J38: 7G | L38: =COUNTIFS(D38:K38,">""") -> 4
B39: 3 | C39: NU | D39: 9E | E39: 10B | G39: 9C | L39: =COUNTIFS(D39:K39,">""") -> 3
B40: 4 | C40: SR | D40: 10D | F40: 9D | I40: 9BS | K40: 10C | L40: =COUNTIFS(D40:K40,">""") -> 4
...

Sheet Tues
A1: CLASS ROUTINE (SCHOOL) - 2026
A2: TUESDAY
A3: SUB | B3: SL | C3: NAME | D3: IST | E3: 2ND | F3: 3RD | G3: 4TH | I3: 5TH | J3: 6TH | K3: 7TH | L3: Total
A4: SUB | B4: SL | C4: NAME | D4: 08.20-09.05 | E4: 09.05-09.45 | F4: 09.45-10.25 | G4: 10.25-11.05 | I4: 11.40-12.25 | J4: 12.25-13.05 | K4: 13.05-13:45
A5: BANGLA | B5: 1 | C5: NA | F5: 8C | I5: 7D | J5: 1OA | L5: =COUNTIFS(D5:K5,">""") -> 3
B6: 2 | C6: GA | D6: 7F | E6: 6E | G6: 10B | K6: 8A | L6: =COUNTIFS(D6:K6,">""") -> 4
B7: 3 | C7: MR | D7: 8D | F7: 9A | G7: 7B | I7: 6B | L7: =COUNTIFS(D7:K7,">""") -> 4
B8: 4 | C8: AS | D8: 6F | F8: 8E | I8: 6G | K8: 7C | L8: =COUNTIFS(D8:K8,">""") -> 4
B9: 5 | C9: SN | D9: 9D | F9: 8B | G9: 7A | I9: 6A | L9: =COUNTIFS(D9:K9,">""") -> 4
B10: 6 | C10: JU | E10: 9H | F10: 9F | J10: 8B | L10: =COUNTIFS(D10:K10,">""") -> 3
B11: 7 | C11: SB | E11: 4E | F11: 9C | I11: 10E | J11: 8F | L11: =COUNTIFS(D11:K11,">""") -> 4
B12: 8 | C12: KT | E12: 3B | G12: 10H | J12: 9E | K12: 7F | L12: =COUNTIFS(D12:K12,">""") -> 4
B13: 9 | C13: TC | D13: 7E | F13: 4G | I13: 1A | J13: 10BS | L13: =COUNTIFS(D13:K13,">""") -> 4
B14: 10 | C14: MJH | D14: 10F | F14: 5B | I14: 2E | J14: 5G | L14: =COUNTIFS(D14:K14,">""") -> 4
B15: 11 | C15: TJA | D15: 3E | F15: 5C | J15: 1B | K15: 2A | L15: =COUNTIFS(D15:K15,">""") -> 4
B16: 12 | C16: ARB | D16: 3F | E16: 10C | G16: 6D | J16: 2G | K16: 8G | L16: =COUNTIFS(D16:K16,">""") -> 5
B17: 13 | C17: UHP | D17: 5D | F17: 4F | G17: 3A | I17: 9BS | K17: 6E | L17: =COUNTIFS(D17:K17,">""") -> 5
B18: 14 | C18: JHB | D18: 4A | E18: 6A | G18: 3C | J18: 2F | L18: =COUNTIFS(D18:K18,">""") -> 4
B19: 15 | C19: TS | D19: 5E | F19: 3G | I19: 2B | K19: 7G | L19: =COUNTIFS(D19:K19,">""") -> 4
B20: 16 | C20: MAI | E20: 5A | F20: 4B | J20: 5F | K20: 2C | L20: =COUNTIFS(D20:K20,">""") -> 4
A21: ENGLISH | B21: 1 | C21: BCB | D21: 10A | G21: 5B | J21: 8C | K21: 9E | L21: =COUNTIFS(D21:K21,">""") -> 4
B22: 2 | C22: KU | D22: 8A | F22: 10C | G22: 5E | K22: 10BS | L22: =COUNTIFS(D22:K22,">""") -> 4
B23: 3 | C23: SHS | E23: 4D | F23: 7F | J23: 9BS | K23: 6B | L23: =COUNTIFS(D23:K23,">""") -> 4
B24: 4 | C24: NH | D24: 5C | F24: 10B | G24: 7C | K24: 8B | L24: =COUNTIFS(D24:K24,">""") -> 4
B25: 5 | C25: SIS | D25: 4G | F25: 7B | G25: 5A | J25: 9B | L25: =COUNTIFS(D25:K25,">""") -> 4
B26: 6 | C26: MSI | E26: 4A | G26: 9D | I26: 10F | K26: 8D | L26: =COUNTIFS(D26:K26,">""") -> 4
B27: 7 | C27: MSH | E27: 5F | G27: 10E | J27: 9F | L27: =COUNTIFS(D27:K27,">""") -> 3
B28: 8 | C28: SJA | D28: 9H | E28: 8F | I28: 7A | J28: 10B | L28: =COUNTIFS(D28:K28,">""") -> 4
B29: 9 | C29: RS | E29: 3A | G29: 6G | J29: 8E | K29: 2B | L29: =COUNTIFS(D29:K29,">""") -> 4
B30: 10 | C30: ZK | D30: 7D | F30: 8G | G30: 6E | I30: 2A | K30: 10A | L30: =COUNTIFS(D30:K30,">""") -> 5
B31: 11 | C31: MAN | D31: 3B | F31: 9E | G31: 5D | J31: 1A | L31: =COUNTIFS(D31:K31,">""") -> 4
B32: 12 | C32: MHM | D32: 10H | E32: 3F | G32: 7F | I32: 5G | K32: 2D | L32: =COUNTIFS(D32:K32,">""") -> 5
B33: 13 | C33: RU | D33: 8C | E33: 7G | I33: 1F | K33: 9C | L33: =COUNTIFS(D33:K33,">""") -> 4
B34: 14 | C34: ISE | E34: 8B | G34: 9A | I34: 1D | J34: 7E | L34: =COUNTIFS(D34:K34,">""") -> 4
B35: 15 | C35: KMA | E35: 4B | G35: 6C | I35: 7G | K35: 8E | L35: =COUNTIFS(D35:K35,">""") -> 4
B36: 16 | C36: KKR | D36: 7A | F36: 3D | G36: 6F | J36: 1G | L36: =COUNTIFS(D36:K36,">""") -> 4
A37: MATH | B37: 1 | C37: MFA | G37: 10A | L37: =COUNTIFS(D37:K37,">""") -> 1
B38: 2 | C38: MOH | E38: 10A | F38: 9B | I38: 9H | L38: =COUNTIFS(D38:K38,">""") -> 3
B39: 3 | C39: NU | D39: 10B | F39: 10F | G39: 8G | J39: 7A | L39: =COUNTIFS(D39:K39,">""") -> 4
B40: 4 | C40: SR | D40: 9BS | E40: 10D | I40: 9D | K40: 6A | L40: =COUNTIFS(D40:K40,">""") -> 4
...

Sheet Wed
A1: CLASS ROUTINE (SCHOOL) - 2026
A2: WEDNESDAY
A3: SUB | B3: SL | C3: NAME | D3: IST | E3: 2ND | F3: 3RD | G3: 4TH | I3: 5TH | J3: 6TH | K3: 7TH | L3: Total
A4: SUB | B4: SL | C4: NAME | D4: 08.20-09.05 | E4: 09.05-09.45 | F4: 09.45-10.25 | G4: 10.25-11.05 | I4: 11.40-12.25 | J4: 12.25-13.05 | K4: 13.05-13:45
A5: BANGLA | B5: 1 | C5: NA | E5: 9B | F5: 10B | J5: 9F | L5: =COUNTIFS(D5:K5,">""") -> 3
B6: 2 | C6: GA | D6: 7D | E6: 10E | G6: 9B | J6: 8A | L6: =COUNTIFS(D6:K6,">""") -> 4
B7: 3 | C7: MR | D7: 6G | E7: 9BS | G7: 8D | J7: 10D | L7: =COUNTIFS(D7:K7,">""") -> 4
B8: 4 | C8: AS | D8: 10D | F8: 8E | G8: 6G | I8: 6F | K8: 8D | L8: =COUNTIFS(D8:K8,">""") -> 5
B9: 5 | C9: SN | D9: 8C | F9: 9D | G9: 6C | J9: 8B | K9: 10F | L9: =COUNTIFS(D9:K9,">""") -> 5
B10: 6 | C10: JU | D10: 8B | F10: 5A | J10: 10A | K10: 9H | L10: =COUNTIFS(D10:K10,">""") -> 4
B11: 7 | C11: SB | D11: 6C | G11: 4E | I11: 2D | K11: 7B | L11: =COUNTIFS(D11:K11,">""") -> 4
B12: 8 | C12: KT | E12: 4C | F12: 9E | I12: 8G | J12: 6B | L12: =COUNTIFS(D12:K12,">""") -> 4
B13: 9 | C13: TC | D13: 8A | E13: 6D | J13: 9C | K13: 7E | L13: =COUNTIFS(D13:K13,">""") -> 4
B14: 10 | C14: MJH | D14: 8E | E14: 9H | G14: 5B | J14: 6F | L14: =COUNTIFS(D14:K14,">""") -> 4
B15: 11 | C15: TJA | E15: 7G | F15: 10BS | J15: 9D | K15: 2F-EHW | L15: =COUNTIFS(D15:K15,">""") -> 4
B16: 12 | C16: ARB | D16: 9E | E16: 7A | F16: 6D | L16: =COUNTIFS(D16:K16,">""") -> 3
B17: 13 | C17: UHP | E17: 8F | G17: 5D | I17: 6E | K17: 9BS | L17: =COUNTIFS(D17:K17,">""") -> 4
B18: 14 | C18: JHB | E18: 10H | F18: 5G | I18: 7C | K18: 6A | L18: =COUNTIFS(D18:K18,">""") -> 4
B19: 15 | C19: TS | D19: 5C | E19: 4D | I19: 5E | J19: 7G | L19: =COUNTIFS(D19:K19,">""") -> 4
B20: 16 | C20: MAI | D20: 3D | F20: 5F | G20: 4B | J20: 7E | L20: =COUNTIFS(D20:K20,">""") -> 4
A21: ENGLISH | B21: 1 | C21: BCB | E21: 8C | F21: 5B | I21: 7E | J21: 6A | L21: =COUNTIFS(D21:K21,">""") -> 4
B22: 2 | C22: KU | D22: 5E | F22: 9B | I22: 9H | J22: 10BS | L22: =COUNTIFS(D22:K22,">""") -> 4
B23: 3 | C23: SHS | D23: 6B | F23: 9C | I23: 10E | K23: 8A | L23: =COUNTIFS(D23:K23,">""") -> 4
B24: 4 | C24: NH | D24: 9A | G24: 5C | I24: 6D | K24: 7C | L24: =COUNTIFS(D24:K24,">""") -> 4
B25: 5 | C25: SIS | D25: 9B | F25: 4G | I25: 10C | J25: 8F | L25: =COUNTIFS(D25:K25,">""") -> 4
B26: 6 | C26: MSI | D26: 3E | F26: 10H | G26: 4A | K26: 9D | L26: =COUNTIFS(D26:K26,">""") -> 4
B27: 7 | C27: MSH | D27: 5F | E27: 7D | G27: 6A | J27: 2E | L27: =COUNTIFS(D27:K27,">""") -> 4
B28: 8 | C28: SJA | E28: 10B | G28: 9H | J28: 7A | K28: 2C | L28: =COUNTIFS(D28:K28,">""") -> 4
B29: 9 | C29: RS | D29: 3A | F29: 10F | I29: 9D | J29: 8E | L29: =COUNTIFS(D29:K29,">""") -> 4
B30: 10 | C30: ZK | E30: 3C | G30: 8G | J30: 2A | L30: =COUNTIFS(D30:K30,">""") -> 3
B31: 11 | C31: MAN | E31: 7B | F31: 5D | I31: 1A | K31: 6E | L31: =COUNTIFS(D31:K31,">""") -> 4
B32: 12 | C32: MHM | D32: 9BS | F32: 8D | I32: 7F | L32: =COUNTIFS(D32:K32,">""") -> 3
B33: 13 | C33: RU | D33: 5A | E33: 4F | G33: 7G | I33: 8C | J33: 1F | L33: =COUNTIFS(D33:K33,">""") -> 5
B34: 14 | C34: ISE | E34: 10D | F34: 6F | J34: 1D | K34: 8B | L34: =COUNTIFS(D34:K34,">""") -> 4
B35: 15 | C35: KMA | D35: 3G | F35: 4B | I35: 1C | J35: 2G | L35: =COUNTIFS(D35:K35,">""") -> 4
B36: 16 | C36: KKR | D36: 8G | E36: 5G | G36: 3D | I36: 2A-Ehw | J36: 2F | L36: =COUNTIFS(D36:K36,">""") -> 5
A37: MATH | B37: 1 | C37: MFA | G37: 10E | L37: =COUNTIFS(D37:K37,">""") -> 1
B38: 2 | C38: MOH | E38: 10F | G38: 8C | I38: 7G | L38: =COUNTIFS(D38:K38,">""") -> 3
B39: 3 | C39: NU | E39: 9E | G39: 9C | I39: 7A | J39: 10B | L39: =COUNTIFS(D39:K39,">""") -> 4
B40: 4 | C40: SR | D40: 10C | F40: 10D | J40: 9BS | L40: =COUNTIFS(D40:K40,">""") -> 3
...

Sheet Thurs
A1: CLASS ROUTINE (SCHOOL) - 2026
A2: THURSDAY
A3: SUB | B3: SL | C3: NAME | D3: IST | E3: 2ND | F3: 3RD | G3: 4TH | I3: 5TH | J3: 6TH | K3: 7TH | L3: Total
A4: SUB | B4: SL | C4: NAME | D4: 08.20-09.05 | E4: 09.05-09.45 | F4: 09.45-10.25 | G4: 10.25-11.05 | I4: 11.40-12.25 | J4: 12.25-13.05 | K4: 13.05-13:45
A5: BANGLA | B5: 1 | C5: NA | E5: 10A | G5: 8C | J5: 7D | L5: =COUNTIFS(D5:K5,">""") -> 3
B6: 2 | C6: GA | D6: 7D | F6: 7F | I6: 6E | J6: 10B | L6: =COUNTIFS(D6:K6,">""") -> 4
B7: 3 | C7: MR | D7: 9A | E7: 7B | G7: 6B | J7: 6G | L7: =COUNTIFS(D7:K7,">""") -> 4
B8: 4 | C8: AS | D8: 10D | E8: 9A | J8: 7C | K8: 8D | L8: =COUNTIFS(D8:K8,">""") -> 4
B9: 5 | C9: SN | D9: 7A | F9: 6A | I9: 8C | K9: 9D | L9: =COUNTIFS(D9:K9,">""") -> 4
B10: 6 | C10: JU | D10: 5F | I10: 5A | K10: 9F | L10: =COUNTIFS(D10:K10,">""") -> 3
B11: 7 | C11: SB | D11: 9C | F11: 2D | I11: 10E | K11: 8F | L11: =COUNTIFS(D11:K11,">""") -> 4
B12: 8 | C12: KT | D12: 7F | F12: 10H | I12: 8G | K12: 4C | L12: =COUNTIFS(D12:K12,">""") -> 4
B13: 9 | C13: TC | D13: 10BS | E13: 1A | G13: 8A | K13: 4G | L13: =COUNTIFS(D13:K13,">""") -> 4
B14: 10 | C14: MJH | D14: 2E | E14: 2D-BHw | G14: 5G | J14: 10F | K14: 9H | L14: =COUNTIFS(D14:K14,">""") -> 5
B15: 11 | C15: TJA | D15: 2A | E15: 1B | G15: 5C | I15: 5E | J15: 3E | L15: =COUNTIFS(D15:K15,">""") -> 5
B16: 12 | C16: ARB | D16: 8G | F16: 2G | G16: 7A | J16: 3F | K16: 10C | L16: =COUNTIFS(D16:K16,">""") -> 5
B17: 13 | C17: UHP | D17: 8F | E17: 5D | G17: 10C | I17: 3A | K17: 4F | L17: =COUNTIFS(D17:K17,">""") -> 5
B18: 14 | C18: JHB | D18: 2F | F18: 5B | G18: 7C | K18: 3C | L18: =COUNTIFS(D18:K18,">""") -> 4
B19: 15 | C19: TS | D19: 1D | F19: 2B | J19: 3G | K19: 4D | L19: =COUNTIFS(D19:K19,">""") -> 4
B20: 16 | C20: MAI | E20: 1C | F20: 2C | I20: 7E | K20: 3D | L20: =COUNTIFS(D20:K20,">""") -> 4
A21: ENGLISH | B21: 1 | C21: BCB | D21: 9E | F21: 7E | J21: 5B | L21: =COUNTIFS(D21:K21,">""") -> 3
B22: 2 | C22: KU | E22: 9B | F22: 8A | J22: 5E | K22: 6C | L22: =COUNTIFS(D22:K22,">""") -> 4
B23: 3 | C23: SHS | E23: 7F | G23: 9BS | I23: 8A | J23: 4D | L23: =COUNTIFS(D23:K23,">""") -> 4
B24: 4 | C24: NH | E24: 5C | G24: 8B | I24: 9A | K24: 10B | L24: =COUNTIFS(D24:K24,">""") -> 4
B25: 5 | C25: SIS | E25: 6D | F25: 5A | I25: 10C | J25: 7B | L25: =COUNTIFS(D25:K25,">""") -> 4
B26: 6 | C26: MSI | D26: 10F | E26: 6B | G26: 9D | I26: 8D | K26: 3E | L26: =COUNTIFS(D26:K26,">""") -> 5
B27: 7 | C27: MSH | D27: 10E | E27: 2E | I27: 9F | J27: 5F | L27: =COUNTIFS(D27:K27,">""") -> 4
B28: 8 | C28: SJA | D28: 6G | E28: 7A | G28: 2C | I28: 4C | L28: =COUNTIFS(D28:K28,">""") -> 4
B29: 9 | C29: RS | D29: 2B | E29: 6G | G29: 2E-Ehw | K29: 7C | L29: =COUNTIFS(D29:K29,">""") -> 4
B30: 10 | C30: ZK | D30: 10A | F30: 7D | G30: 9F | J30: 6E | L30: =COUNTIFS(D30:K30,">""") -> 4
B31: 11 | C31: MAN | D31: 5D | E31: 10BS | G31: 7B | I31: 3B | K31: 6E | L31: =COUNTIFS(D31:K31,">""") -> 5
B32: 12 | C32: MHM | D32: 2D | G32: 10H | I32: 3F | K32: 9BS | L32: =COUNTIFS(D32:K32,">""") -> 4
B33: 13 | C33: RU | E33: 8C | G33: 10D | J33: 4F | K33: 9C | L33: =COUNTIFS(D33:K33,">""") -> 4
B34: 14 | C34: ISE | D34: 6F | G34: 6C | J34: 7E | K34: 4E | L34: =COUNTIFS(D34:K34,">""") -> 4
B35: 15 | C35: KMA | D35: 7G | E35: 2G | G35: 1C | I35: 3G | J35: 8E | L35: =COUNTIFS(D35:K35,">""") -> 5
B36: 16 | C36: KKR | D36: 1G | F36: 2F | I36: 5G | J36: 8G | L36: =COUNTIFS(D36:K36,">""") -> 4
A37: MATH | B37: 1 | C37: MFA | G37: 10E | L37: =COUNTIFS(D37:K37,">""") -> 1
B38: 2 | C38: MOH | D38: 9H | E38: 10F | G38: 9B | J38: 10A | L38: =COUNTIFS(D38:K38,">""") -> 4
B39: 3 | C39: NU | E39: 8G | F39: 9E | I39: 10F | J39: 9C | L39: =COUNTIFS(D39:K39,">""") -> 4
B40: 4 | C40: SR | D40: 8C | F40: 10C | I40: 7F | J40: 6A | L40: =COUNTIFS(D40:K40,">""") -> 4
...

Sheet Acct of Class
A2: Total Class
A3: SUB | B3: SL | C3: NAME | D3: SUN | E3: MON | F3: TUE | G3: WED | H3: THU | I3: Total
A4: BANGLA | B4: 1 | C4: NA | D4: =Sun!L5 -> 3 | E4: =Mon!L5 -> 3 | F4: =Tues!L5 -> 3 | G4: =Wed!L5 -> 3 | H4: =Thurs!L5 -> 3 | I4: =SUM(D4:H4) -> 15
B5: 2 | C5: GA | D5: =Sun!L6 -> 4 | E5: =Mon!L6 -> 4 | F5: =Tues!L6 -> 4 | G5: =Wed!L6 -> 4 | H5: =Thurs!L6 -> 4 | I5: =SUM(D5:H5) -> 20
B6: 3 | C6: MR | D6: =Sun!L7 -> 4 | E6: =Mon!L7 -> 4 | F6: =Tues!L7 -> 4 | G6: =Wed!L7 -> 4 | H6: =Thurs!L7 -> 4 | I6: =SUM(D6:H6) -> 20
B7: 4 | C7: AS | D7: =Sun!L8 -> 3 | E7: =Mon!L8 -> 4 | F7: =Tues!L8 -> 4 | G7: =Wed!L8 -> 5 | H7: =Thurs!L8 -> 4 | I7: =SUM(D7:H7) -> 20
B8: 5 | C8: SN | D8: =Sun!L9 -> 3 | E8: =Mon!L9 -> 4 | F8: =Tues!L9 -> 4 | G8: =Wed!L9 -> 5 | H8: =Thurs!L9 -> 4 | I8: =SUM(D8:H8) -> 20
B9: 6 | C9: JU | D9: =Sun!L10 -> 2 | E9: =Mon!L10 -> 3 | F9: =Tues!L10 -> 3 | G9: =Wed!L10 -> 4 | H9: =Thurs!L10 -> 3 | I9: =SUM(D9:H9) -> 15
B10: 7 | C10: SB | D10: =Sun!L11 -> 5 | E10: =Mon!L11 -> 4 | F10: =Tues!L11 -> 4 | G10: =Wed!L11 -> 4 | H10: =Thurs!L11 -> 4 | I10: =SUM(D10:H10) -> 21
B11: 8 | C11: KT | D11: =Sun!L12 -> 5 | E11: =Mon!L12 -> 4 | F11: =Tues!L12 -> 4 | G11: =Wed!L12 -> 4 | H11: =Thurs!L12 -> 4 | I11: =SUM(D11:H11) -> 21
B12: 9 | C12: TC | D12: =Sun!L13 -> 5 | E12: =Mon!L13 -> 4 | F12: =Tues!L13 -> 4 | G12: =Wed!L13 -> 4 | H12: =Thurs!L13 -> 4 | I12: =SUM(D12:H12) -> 21
B13: 10 | C13: MJH | D13: =Sun!L14 -> 5 | E13: =Mon!L14 -> 3 | F13: =Tues!L14 -> 4 | G13: =Wed!L14 -> 4 | H13: =Thurs!L14 -> 5 | I13: =SUM(D13:H13) -> 21
B14: 11 | C14: TJA | D14: =Sun!L15 -> 3 | E14: =Mon!L15 -> 5 | F14: =Tues!L15 -> 4 | G14: =Wed!L15 -> 4 | H14: =Thurs!L15 -> 5 | I14: =SUM(D14:H14) -> 21
B15: 12 | C15: ARB | D15: =Sun!L16 -> 4 | E15: =Mon!L16 -> 4 | F15: =Tues!L16 -> 5 | G15: =Wed!L16 -> 3 | H15: =Thurs!L16 -> 5 | I15: =SUM(D15:H15) -> 21
B16: 13 | C16: UHP | D16: =Sun!L17 -> 3 | E16: =Mon!L17 -> 4 | F16: =Tues!L17 -> 5 | G16: =Wed!L17 -> 4 | H16: =Thurs!L17 -> 5 | I16: =SUM(D16:H16) -> 21
... B19: 16 | C19: MAI | D19: =Sun!L20 -> 4 | E19: =Mon!L20 -> 4 | F19: =Tues!L20 -> 4 | G19: =Wed!L20 -> 4 | H19: =Thurs!L20 -> 4 | I19: =SUM(D19:H19) -> 20
A20: ENGLISH | B20: 1 | C20: BCB | D20: =Sun!L21 -> 4 | E20: =Mon!L21 -> 3 | F20: =Tues!L21 -> 4 | G20: =Wed!L21 -> 4 | H20: =Thurs!L21 -> 3 | I20: =SUM(D20:H20) -> 18
B21: 2 | C21: KU | D21: =Sun!L22 -> 4 | E21: =Mon!L22 -> 4 | F21: =Tues!L22 -> 4 | G21: =Wed!L22 -> 4 | H21: =Thurs!L22 -> 4 | I21: =SUM(D21:H21) -> 20
B22: 3 | C22: SHS | D22: =Sun!L23 -> 5 | E22: =Mon!L23 -> 3 | F22: =Tues!L23 -> 4 | G22: =Wed!L23 -> 4 | H22: =Thurs!L23 -> 4 | I22: =SUM(D22:H22) -> 20
B23: 4 | C23: NH | D23: =Sun!L24 -> 4 | E23: =Mon!L24 -> 4 | F23: =Tues!L24 -> 4 | G23: =Wed!L24 -> 4 | H23: =Thurs!L24 -> 4 | I23: =SUM(D23:H23) -> 20
B24: 5 | C24: SIS | D24: =Sun!L25 -> 4 | E24: =Mon!L25 -> 4 | F24: =Tues!L25 -> 4 | G24: =Wed!L25 -> 4 | H24: =Thurs!L25 -> 4 | I24: =SUM(D24:H24) -> 20
B25: 6 | C25: MSI | D25: =Sun!L26 -> 4 | E25: =Mon!L26 -> 4 | F25: =Tues!L26 -> 4 | G25: =Wed!L26 -> 4 | H25: =Thurs!L26 -> 5 | I25: =SUM(D25:H25) -> 21
B26: 7 | C26: MSH | D26: =Sun!L27 -> 5 | E26: =Mon!L27 -> 4 | F26: =Tues!L27 -> 3 | G26: =Wed!L27 -> 4 | H26: =Thurs!L27 -> 4 | I26: =SUM(D26:H26) -> 20
B27: 8 | C27: SJA | D27: =Sun!L28 -> 4 | E27: =Mon!L28 -> 4 | F27: =Tues!L28 -> 4 | G27: =Wed!L28 -> 4 | H27: =Thurs!L28 -> 4 | I27: =SUM(D27:H27) -> 20
B28: 9 | C28: RS | D28: =Sun!L29 -> 4 | E28: =Mon!L29 -> 5 | F28: =Tues!L29 -> 4 | G28: =Wed!L29 -> 4 | H28: =Thurs!L29 -> 4 | I28: =SUM(D28:H28) -> 21
B29: 10 | C29: ZK | D29: =Sun!L30 -> 5 | E29: =Mon!L30 -> 4 | F29: =Tues!L30 -> 5 | G29: =Wed!L30 -> 3 | H29: =Thurs!L30 -> 4 | I29: =SUM(D29:H29) -> 21
B30: 11 | C30: MAN | D30: =Sun!L31 -> 4 | E30: =Mon!L31 -> 4 | F30: =Tues!L31 -> 4 | G30: =Wed!L31 -> 4 | H30: =Thurs!L31 -> 5 | I30: =SUM(D30:H30) -> 21
B31: 12 | C31: MHM | D31: =Sun!L32 -> 4 | E31: =Mon!L32 -> 4 | F31: =Tues!L32 -> 5 | G31: =Wed!L32 -> 3 | H31: =Thurs!L32 -> 4 | I31: =SUM(D31:H31) -> 20
B32: 13 | C32: RU | D32: =Sun!L33 -> 4 | E32: =Mon!L33 -> 4 | F32: =Tues!L33 -> 4 | G32: =Wed!L33 -> 5 | H32: =Thurs!L33 -> 4 | I32: =SUM(D32:H32) -> 21
... B35: 16 | C35: KKR | D35: =Sun!L36 -> 4 | E35: =Mon!L36 -> 4 | F35: =Tues!L36 -> 4 | G35: =Wed!L36 -> 5 | H35: =Thurs!L36 -> 4 | I35: =SUM(D35:H35) -> 21
A36: MATH | B36: 1 | C36: MFA | D36: =Sun!L37 -> 1 | E36: =Mon!L37 -> 1 | F36: =Tues!L37 -> 1 | G36: =Wed!L37 -> 1 | H36: =Thurs!L37 -> 1 | I36: =SUM(D36:H36) -> 5
B37: 2 | C37: MOH | D37: =Sun!L38 -> 4 | E37: =Mon!L38 -> 4 | F37: =Tues!L38 -> 3 | G37: =Wed!L38 -> 3 | H37: =Thurs!L38 -> 4 | I37: =SUM(D37:H37) -> 18
B38: 3 | C38: NU | D38: =Sun!L39 -> 4 | E38: =Mon!L39 -> 3 | F38: =Tues!L39 -> 4 | G38: =Wed!L39 -> 4 | H38: =Thurs!L39 -> 4 | I38: =SUM(D38:H38) -> 19
B39: 4 | C39: SR | D39: =Sun!L40 -> 4 | E39: =Mon!L40 -> 4 | F39: =Tues!L40 -> 4 | G39: =Wed!L40 -> 3 | H39: =Thurs!L40 -> 4 | I39: =SUM(D39:H39) -> 19
B40: 5 | C40: SAS | D40: =Sun!L41 -> 4 | E40: =Mon!L41 -> 4 | F40: =Tues!L41 -> 4 | G40: =Wed!L41 -> 3 | H40: =Thurs!L41 -> 4 | I40: =SUM(D40:H40) -> 19
B41: 6 | C41: MRU | D41: =Sun!L42 -> 4 | E41: =Mon!L42 -> 4 | F41: =Tues!L42 -> 3 | G41: =Wed!L42 -> 4 | H41: =Thurs!L42 -> 4 | I41: =SUM(D41:H41) -> 19
B42: 7 | C42: MKH | D42: =Sun!L43 -> 4 | E42: =Mon!L43 -> 4 | F42: =Tues!L43 -> 4 | G42: =Wed!L43 -> 3 | H42: =Thurs!L43 -> 4 | I42: =SUM(D42:H42) -> 19
B43: 8 | C43: MAH | D43: =Sun!L44 -> 4 | E43: =Mon!L44 -> 4 | F43: =Tues!L44 -> 4 | G43: =Wed!L44 -> 4 | H43: =Thurs!L44 -> 4 | I43: =SUM(D43:H43) -> 20
B44: 9 | C44: AMR | D44: =Sun!L45 -> 4 | E44: =Mon!L45 -> 4 | F44: =Tues!L45 -> 4 | G44: =Wed!L45 -> 4 | H44: =Thurs!L45 -> 4 | I44: =SUM(D44:H44) -> 20
B45: 10 | C45: MES | D45: =Sun!L46 -> 5 | E45: =Mon!L46 -> 5 | F45: =Tues!L46 -> 4 | G45: =Wed!L46 -> 3 | H45: =Thurs!L46 -> 3 | I45: =SUM(D45:H45) -> 20
...
